<?xml version="1.0" encoding="UTF-8"?>
<!-- Generated by org.testng.reporters.JUnitReportReporter -->
<testsuite hostname="DESKTOP-0NR2IK8" failures="0" tests="3" name="testNG.testNG.SecondTestCase" time="0.016" errors="1" timestamp="2025-07-20T13:00:18 IST" skipped="0">
  <testcase classname="testNG.testNG.SecondTestCase" name="testMethod1" time="0.012">
    <error message="expected:&lt;1&gt; but was:&lt;2&gt;" type="junit.framework.AssertionFailedError">
      <![CDATA[junit.framework.AssertionFailedError: expected:<1> but was:<2>
at junit.framework.Assert.fail(Assert.java:47)
at junit.framework.Assert.failNotEquals(Assert.java:282)
at junit.framework.Assert.assertEquals(Assert.java:64)
at junit.framework.Assert.assertEquals(Assert.java:201)
at junit.framework.Assert.assertEquals(Assert.java:207)
at testNG.testNG.SecondTestCase.testMethod1(SecondTestCase.java:16)
at java.base/jdk.internal.reflect.DirectMethodHandleAccessor.invoke(DirectMethodHandleAccessor.java:103)
at java.base/java.lang.reflect.Method.invoke(Method.java:580)
at org.testng.internal.invokers.MethodInvocationHelper.invokeMethod(MethodInvocationHelper.java:139)
at org.testng.internal.invokers.TestInvoker.invokeMethod(TestInvoker.java:664)
at org.testng.internal.invokers.TestInvoker.invokeTestMethod(TestInvoker.java:228)
at org.testng.internal.invokers.MethodRunner.runInSequence(MethodRunner.java:63)
at org.testng.internal.invokers.TestInvoker$MethodInvocationAgent.invoke(TestInvoker.java:961)
at org.testng.internal.invokers.TestInvoker.invokeTestMethods(TestInvoker.java:201)
at org.testng.internal.invokers.TestMethodWorker.invokeTestMethods(TestMethodWorker.java:148)
at org.testng.internal.invokers.TestMethodWorker.run(TestMethodWorker.java:128)
at java.base/java.util.ArrayList.forEach(ArrayList.java:1597)
at org.testng.TestRunner.privateRun(TestRunner.java:819)
at org.testng.TestRunner.run(TestRunner.java:619)
at org.testng.SuiteRunner.runTest(SuiteRunner.java:443)
at org.testng.SuiteRunner.runSequentially(SuiteRunner.java:437)
at org.testng.SuiteRunner.privateRun(SuiteRunner.java:397)
at org.testng.SuiteRunner.run(SuiteRunner.java:336)
at org.testng.SuiteRunnerWorker.runSuite(SuiteRunnerWorker.java:52)
at org.testng.SuiteRunnerWorker.run(SuiteRunnerWorker.java:95)
at org.testng.TestNG.runSuitesSequentially(TestNG.java:1301)
at org.testng.TestNG.runSuitesLocally(TestNG.java:1228)
at org.testng.TestNG.runSuites(TestNG.java:1134)
at org.testng.TestNG.run(TestNG.java:1101)
at org.testng.remote.AbstractRemoteTestNG.run(AbstractRemoteTestNG.java:115)
at org.testng.remote.RemoteTestNG.initAndRun(RemoteTestNG.java:293)
at org.testng.remote.RemoteTestNG.main(RemoteTestNG.java:91)
]]>
    </error>
  </testcase> <!-- testMethod1 -->
  <testcase classname="testNG.testNG.SecondTestCase" name="testMethod3" time="0.002"/>
  <testcase classname="testNG.testNG.SecondTestCase" name="testMethod2" time="0.002"/>
</testsuite> <!-- testNG.testNG.SecondTestCase -->
